Workbook

Sheet Roster
A1: ROSTER - Ultimate Frisbee Team
A4: Full Name | B4: Dues Amount ($) | C4: Dues Paid? | D4: Role | E4: Status | F4: Notes | G4: Guest Of
A5: ='Access Codes'!A6 -> At | B5: {=IFERROR(INDEX('Player Balances'!$B$7:$B$206,MATCH(A5,'Player Balances'!$A$7:$A$206,0)),"")} -> 0 | C5: =IF(A5="","",IF(OR(D5="Coach",D5="Treasurer"),"Waived",IF(OR(B5="",B5=0),"",IF(SUMIFS(Transactions!$F$7:$F$989,Transactions!$D$7:$D$989,"Income",Transactions!$C$7:$C$989,"Dues",Transactions!$E$7:$E$989,A5)>=B5,"Paid",IF(SUMIFS(Transactions!$F$7:$F$989,Transactions!$D$7:$D$989,"Income",Transactions!$C$7:$C$989,"Dues",Transactions!$E$7:$E$989,A5)>0,"Partial","Unpaid"))))) | D5: ='Access Codes'!C6 -> Captain | E5: ='Access Codes'!D6 -> Active
A6: ='Access Codes'!A7 -> Alex Warrington | B6: {=IFERROR(INDEX('Player Balances'!$B$7:$B$206,MATCH(A6,'Player Balances'!$A$7:$A$206,0)),"")} -> 0 | C6: =IF(A6="","",IF(OR(D6="Coach",D6="Treasurer"),"Waived",IF(OR(B6="",B6=0),"",IF(SUMIFS(Transactions!$F$7:$F$989,Transactions!$D$7:$D$989,"Income",Transactions!$C$7:$C$989,"Dues",Transactions!$E$7:$E$989,A6)>=B6,"Paid",IF(SUMIFS(Transactions!$F$7:$F$989,Transactions!$D$7:$D$989,"Income",Transactions!$C$7:$C$989,"Dues",Transactions!$E$7:$E$989,A6)>0,"Partial","Unpaid"))))) | D6: ='Access Codes'!C7 -> Player | E6: ='Access Codes'!D7 -> Active
A7: ='Access Codes'!A8 -> Chris Wohl | B7: {=IFERROR(INDEX('Player Balances'!$B$7:$B$206,MATCH(A7,'Player Balances'!$A$7:$A$206,0)),"")} -> 0 | C7: =IF(A7="","",IF(OR(D7="Coach",D7="Treasurer"),"Waived",IF(OR(B7="",B7=0),"",IF(SUMIFS(Transactions!$F$7:$F$989,Transactions!$D$7:$D$989,"Income",Transactions!$C$7:$C$989,"Dues",Transactions!$E$7:$E$989,A7)>=B7,"Paid",IF(SUMIFS(Transactions!$F$7:$F$989,Transactions!$D$7:$D$989,"Income",Transactions!$C$7:$C$989,"Dues",Transactions!$E$7:$E$989,A7)>0,"Partial","Unpaid"))))) | D7: ='Access Codes'!C8 -> Player | E7: ='Access Codes'!D8 -> Active | F7: Paid $75
A8: ='Access Codes'!A9 -> Darra Reppermund | B8: {=IFERROR(INDEX('Player Balances'!$B$7:$B$206,MATCH(A8,'Player Balances'!$A$7:$A$206,0)),"")} -> 0 | C8: =IF(A8="","",IF(OR(D8="Coach",D8="Treasurer"),"Waived",IF(OR(B8="",B8=0),"",IF(SUMIFS(Transactions!$F$7:$F$989,Transactions!$D$7:$D$989,"Income",Transactions!$C$7:$C$989,"Dues",Transactions!$E$7:$E$989,A8)>=B8,"Paid",IF(SUMIFS(Transactions!$F$7:$F$989,Transactions!$D$7:$D$989,"Income",Transactions!$C$7:$C$989,"Dues",Transactions!$E$7:$E$989,A8)>0,"Partial","Unpaid"))))) | D8: ='Access Codes'!C9 -> Player | E8: ='Access Codes'!D9 -> Active
A9: ='Access Codes'!A10 -> Dylan Best | B9: {=IFERROR(INDEX('Player Balances'!$B$7:$B$206,MATCH(A9,'Player Balances'!$A$7:$A$206,0)),"")} -> 0 | C9: =IF(A9="","",IF(OR(D9="Coach",D9="Treasurer"),"Waived",IF(OR(B9="",B9=0),"",IF(SUMIFS(Transactions!$F$7:$F$989,Transactions!$D$7:$D$989,"Income",Transactions!$C$7:$C$989,"Dues",Transactions!$E$7:$E$989,A9)>=B9,"Paid",IF(SUMIFS(Transactions!$F$7:$F$989,Transactions!$D$7:$D$989,"Income",Transactions!$C$7:$C$989,"Dues",Transactions!$E$7:$E$989,A9)>0,"Partial","Unpaid"))))) | D9: ='Access Codes'!C10 -> Player | E9: ='Access Codes'!D10 -> Active
A10: ='Access Codes'!A11 -> Griffin O'Neal-Freeman | B10: {=IFERROR(INDEX('Player Balances'!$B$7:$B$206,MATCH(A10,'Player Balances'!$A$7:$A$206,0)),"")} -> 0 | C10: =IF(A10="","",IF(OR(D10="Coach",D10="Treasurer"),"Waived",IF(OR(B10="",B10=0),"",IF(SUMIFS(Transactions!$F$7:$F$989,Transactions!$D$7:$D$989,"Income",Transactions!$C$7:$C$989,"Dues",Transactions!$E$7:$E$989,A10)>=B10,"Paid",IF(SUMIFS(Transactions!$F$7:$F$989,Transactions!$D$7:$D$989,"Income",Transactions!$C$7:$C$989,"Dues",Transactions!$E$7:$E$989,A10)>0,"Partial","Unpaid"))))) | D10: ='Access Codes'!C11 -> Player | E10: ='Access Codes'!D11 -> Active
A11: ='Access Codes'!A12 -> Haley Young | B11: {=IFERROR(INDEX('Player Balances'!$B$7:$B$206,MATCH(A11,'Player Balances'!$A$7:$A$206,0)),"")} -> 0 | C11: =IF(A11="","",IF(OR(D11="Coach",D11="Treasurer"),"Waived",IF(OR(B11="",B11=0),"",IF(SUMIFS(Transactions!$F$7:$F$989,Transactions!$D$7:$D$989,"Income",Transactions!$C$7:$C$989,"Dues",Transactions!$E$7:$E$989,A11)>=B11,"Paid",IF(SUMIFS(Transactions!$F$7:$F$989,Transactions!$D$7:$D$989,"Income",Transactions!$C$7:$C$989,"Dues",Transactions!$E$7:$E$989,A11)>0,"Partial","Unpaid"))))) | D11: ='Access Codes'!C12 -> Player | E11: ='Access Codes'!D12 -> Active
A12: ='Access Codes'!A13 -> Harry Park | B12: {=IFERROR(INDEX('Player Balances'!$B$7:$B$206,MATCH(A12,'Player Balances'!$A$7:$A$206,0)),"")} -> 0 | C12: =IF(A12="","",IF(OR(D12="Coach",D12="Treasurer"),"Waived",IF(OR(B12="",B12=0),"",IF(SUMIFS(Transactions!$F$7:$F$989,Transactions!$D$7:$D$989,"Income",Transactions!$C$7:$C$989,"Dues",Transactions!$E$7:$E$989,A12)>=B12,"Paid",IF(SUMIFS(Transactions!$F$7:$F$989,Transactions!$D$7:$D$989,"Income",Transactions!$C$7:$C$989,"Dues",Transactions!$E$7:$E$989,A12)>0,"Partial","Unpaid"))))) | D12: ='Access Codes'!C13 -> Player | E12: ='Access Codes'!D13 -> Active
A13: ='Access Codes'!A14 -> Ian Piper | B13: {=IFERROR(INDEX('Player Balances'!$B$7:$B$206,MATCH(A13,'Player Balances'!$A$7:$A$206,0)),"")} -> 0 | C13: =IF(A13="","",IF(OR(D13="Coach",D13="Treasurer"),"Waived",IF(OR(B13="",B13=0),"",IF(SUMIFS(Transactions!$F$7:$F$989,Transactions!$D$7:$D$989,"Income",Transactions!$C$7:$C$989,"Dues",Transactions!$E$7:$E$989,A13)>=B13,"Paid",IF(SUMIFS(Transactions!$F$7:$F$989,Transactions!$D$7:$D$989,"Income",Transactions!$C$7:$C$989,"Dues",Transactions!$E$7:$E$989,A13)>0,"Partial","Unpaid"))))) | D13: ='Access Codes'!C14 -> Player | E13: ='Access Codes'!D14 -> Active
A14: ='Access Codes'!A15 -> Jake Murray | B14: {=IFERROR(INDEX('Player Balances'!$B$7:$B$206,MATCH(A14,'Player Balances'!$A$7:$A$206,0)),"")} -> 0 | C14: =IF(A14="","",IF(OR(D14="Coach",D14="Treasurer"),"Waived",IF(OR(B14="",B14=0),"",IF(SUMIFS(Transactions!$F$7:$F$989,Transactions!$D$7:$D$989,"Income",Transactions!$C$7:$C$989,"Dues",Transactions!$E$7:$E$989,A14)>=B14,"Paid",IF(SUMIFS(Transactions!$F$7:$F$989,Transactions!$D$7:$D$989,"Income",Transactions!$C$7:$C$989,"Dues",Transactions!$E$7:$E$989,A14)>0,"Partial","Unpaid"))))) -> Waived | D14: ='Access Codes'!C15 -> Treasurer | E14: ='Access Codes'!D15 -> Active
A15: ='Access Codes'!A16 -> Jenna Nold | B15: {=IFERROR(INDEX('Player Balances'!$B$7:$B$206,MATCH(A15,'Player Balances'!$A$7:$A$206,0)),"")} -> 0 | C15: =IF(A15="","",IF(OR(D15="Coach",D15="Treasurer"),"Waived",IF(OR(B15="",B15=0),"",IF(SUMIFS(Transactions!$F$7:$F$989,Transactions!$D$7:$D$989,"Income",Transactions!$C$7:$C$989,"Dues",Transactions!$E$7:$E$989,A15)>=B15,"Paid",IF(SUMIFS(Transactions!$F$7:$F$989,Transactions!$D$7:$D$989,"Income",Transactions!$C$7:$C$989,"Dues",Transactions!$E$7:$E$989,A15)>0,"Partial","Unpaid"))))) | D15: ='Access Codes'!C16 -> Captain | E15: ='Access Codes'!D16 -> Active
A16: ='Access Codes'!A17 -> Jimmy Towle | B16: {=IFERROR(INDEX('Player Balances'!$B$7:$B$206,MATCH(A16,'Player Balances'!$A$7:$A$206,0)),"")} -> 0 | C16: =IF(A16="","",IF(OR(D16="Coach",D16="Treasurer"),"Waived",IF(OR(B16="",B16=0),"",IF(SUMIFS(Transactions!$F$7:$F$989,Transactions!$D$7:$D$989,"Income",Transactions!$C$7:$C$989,"Dues",Transactions!$E$7:$E$989,A16)>=B16,"Paid",IF(SUMIFS(Transactions!$F$7:$F$989,Transactions!$D$7:$D$989,"Income",Transactions!$C$7:$C$989,"Dues",Transactions!$E$7:$E$989,A16)>0,"Partial","Unpaid"))))) | D16: ='Access Codes'!C17 -> Player | E16: ='Access Codes'!D17 -> Active
A17: ='Access Codes'!A18 -> Kailey Rugani | B17: {=IFERROR(INDEX('Player Balances'!$B$7:$B$206,MATCH(A17,'Player Balances'!$A$7:$A$206,0)),"")} -> 0 | C17: =IF(A17="","",IF(OR(D17="Coach",D17="Treasurer"),"Waived",IF(OR(B17="",B17=0),"",IF(SUMIFS(Transactions!$F$7:$F$989,Transactions!$D$7:$D$989,"Income",Transactions!$C$7:$C$989,"Dues",Transactions!$E$7:$E$989,A17)>=B17,"Paid",IF(SUMIFS(Transactions!$F$7:$F$989,Transactions!$D$7:$D$989,"Income",Transactions!$C$7:$C$989,"Dues",Transactions!$E$7:$E$989,A17)>0,"Partial","Unpaid"))))) | D17: ='Access Codes'!C18 -> Player | E17: ='Access Codes'!D18 -> Active
A18: ='Access Codes'!A19 -> Kasey Schock | B18: {=IFERROR(INDEX('Player Balances'!$B$7:$B$206,MATCH(A18,'Player Balances'!$A$7:$A$206,0)),"")} -> 0 | C18: =IF(A18="","",IF(OR(D18="Coach",D18="Treasurer"),"Waived",IF(OR(B18="",B18=0),"",IF(SUMIFS(Transactions!$F$7:$F$989,Transactions!$D$7:$D$989,"Income",Transactions!$C$7:$C$989,"Dues",Transactions!$E$7:$E$989,A18)>=B18,"Paid",IF(SUMIFS(Transactions!$F$7:$F$989,Transactions!$D$7:$D$989,"Income",Transactions!$C$7:$C$989,"Dues",Transactions!$E$7:$E$989,A18)>0,"Partial","Unpaid"))))) | D18: ='Access Codes'!C19 -> Player | E18: ='Access Codes'!D19 -> Active
A19: ='Access Codes'!A20 -> Kevin Nicholl | B19: {=IFERROR(INDEX('Player Balances'!$B$7:$B$206,MATCH(A19,'Player Balances'!$A$7:$A$206,0)),"")} -> 0 | C19: =IF(A19="","",IF(OR(D19="Coach",D19="Treasurer"),"Waived",IF(OR(B19="",B19=0),"",IF(SUMIFS(Transactions!$F$7:$F$989,Transactions!$D$7:$D$989,"Income",Transactions!$C$7:$C$989,"Dues",Transactions!$E$7:$E$989,A19)>=B19,"Paid",IF(SUMIFS(Transactions!$F$7:$F$989,Transactions!$D$7:$D$989,"Income",Transactions!$C$7:$C$989,"Dues",Transactions!$E$7:$E$989,A19)>0,"Partial","Unpaid"))))) | D19: ='Access Codes'!C20 -> Player | E19: ='Access Codes'!D20 -> Active
... A39: ='Access Codes'!A40 -> Nick Blair | B39: {=IFERROR(INDEX('Player Balances'!$B$7:$B$206,MATCH(A39,'Player Balances'!$A$7:$A$206,0)),"")} -> 0 | C39: =IF(A39="","",IF(OR(D39="Coach",D39="Treasurer"),"Waived",IF(OR(B39="",B39=0),"",IF(SUMIFS(Transactions!$F$7:$F$989,Transactions!$D$7:$D$989,"Income",Transactions!$C$7:$C$989,"Dues",Transactions!$E$7:$E$989,A39)>=B39,"Paid",IF(SUMIFS(Transactions!$F$7:$F$989,Transactions!$D$7:$D$989,"Income",Transactions!$C$7:$C$989,"Dues",Transactions!$E$7:$E$989,A39)>0,"Partial","Unpaid"))))) | D39: ='Access Codes'!C40 -> Support | E39: ='Access Codes'!D40 -> Active
A40: ='Access Codes'!A41 -> Lily Nguyen | B40: {=IFERROR(INDEX('Player Balances'!$B$7:$B$206,MATCH(A40,'Player Balances'!$A$7:$A$206,0)),"")} -> 0 | C40: =IF(A40="","",IF(OR(D40="Coach",D40="Treasurer"),"Waived",IF(OR(B40="",B40=0),"",IF(SUMIFS(Transactions!$F$7:$F$989,Transactions!$D$7:$D$989,"Income",Transactions!$C$7:$C$989,"Dues",Transactions!$E$7:$E$989,A40)>=B40,"Paid",IF(SUMIFS(Transactions!$F$7:$F$989,Transactions!$D$7:$D$989,"Income",Transactions!$C$7:$C$989,"Dues",Transactions!$E$7:$E$989,A40)>0,"Partial","Unpaid"))))) | D40: ='Access Codes'!C41 -> Support | E40: ='Access Codes'!D41 -> Active | G40: Ryan Kindell
A41: ='Access Codes'!A42 -> Griff Soren | B41: {=IFERROR(INDEX('Player Balances'!$B$7:$B$206,MATCH(A41,'Player Balances'!$A$7:$A$206,0)),"")} -> 0 | C41: =IF(A41="","",IF(OR(D41="Coach",D41="Treasurer"),"Waived",IF(OR(B41="",B41=0),"",IF(SUMIFS(Transactions!$F$7:$F$989,Transactions!$D$7:$D$989,"Income",Transactions!$C$7:$C$989,"Dues",Transactions!$E$7:$E$989,A41)>=B41,"Paid",IF(SUMIFS(Transactions!$F$7:$F$989,Transactions!$D$7:$D$989,"Income",Transactions!$C$7:$C$989,"Dues",Transactions!$E$7:$E$989,A41)>0,"Partial","Unpaid"))))) | D41: ='Access Codes'!C42 -> Support | E41: ='Access Codes'!D42 -> Active | G41: Griffin O'Neal-Freeman
A42: ='Access Codes'!A43 -> Griff Alice | B42: {=IFERROR(INDEX('Player Balances'!$B$7:$B$206,MATCH(A42,'Player Balances'!$A$7:$A$206,0)),"")} -> 0 | C42: =IF(A42="","",IF(OR(D42="Coach",D42="Treasurer"),"Waived",IF(OR(B42="",B42=0),"",IF(SUMIFS(Transactions!$F$7:$F$989,Transactions!$D$7:$D$989,"Income",Transactions!$C$7:$C$989,"Dues",Transactions!$E$7:$E$989,A42)>=B42,"Paid",IF(SUMIFS(Transactions!$F$7:$F$989,Transactions!$D$7:$D$989,"Income",Transactions!$C$7:$C$989,"Dues",Transactions!$E$7:$E$989,A42)>0,"Partial","Unpaid"))))) | D42: ='Access Codes'!C43 -> Support | E42: ='Access Codes'!D43 -> Active | G42: Griffin O'Neal-Freeman

Sheet Events
A4: Event Name | B4: Start Date | C4: End Date | D4: Category | E4: Location | F4: Budgeted Cost ($) | G4: Actual Cost ($) | I4: Split Method | J4: Season Group
A5: May-July Fields | B5: 03/15/2025 | D5: Practice | E5: Dan Marino | F5: 850 | G5: =IFERROR(SUMIFS(Transactions!$F$7:$F$989,Transactions!$G$7:$G$989,A5,Transactions!$D$7:$D$989,"Expense"),0) -> 2326 | I5: Attendance | J5: In-Season 2026
A6: PEC | B6: 46199 | D6: Tournament | E6: Browns Summit | F6: 1310 | G6: 1310 | I6: Attendance | J6: In-Season 2026
A7: SFI | B7: 46227 | D7: Tournament | E7: Holiday Inn Downtown | F7: 1050 | G7: 1050 | I7: Attendance | J7: In-Season 2026
A8: Natties Watch Party | D8: Fundraiser | E8: Goodlander | F8: 0 | G8: -123 | J8: Pre-Season 2026
A9: Fantapalooza | B9: 45706 | D9: Fundraiser | E9: Goodlander | F9: 0 | G9: -956 | J9: Pre-Season 2026
A10: 2025 Fundraising | B10: 45706 | D10: Fundraiser | E10: Mult. | F10: 0 | G10: 1030 | J10: Pre-Season 2026
A11: GHP Sessions | D11: Event | E11: GHP | F11: 600 | G11: =IFERROR(SUMIFS(Transactions!$F$7:$F$989,Transactions!$G$7:$G$989,A11,Transactions!$D$7:$D$989,"Expense"),0) -> 0 | I11: Attendance | J11: Pre-Season 2026
A12: ESC | G12: =IFERROR(SUMIFS(Transactions!$F$7:$F$989,Transactions!$G$7:$G$989,A12,Transactions!$D$7:$D$989,"Expense"),0) -> 5345.86 | I12: Attendance | J12: In-Season 2026
A13: Sectionals | G13: =IFERROR(SUMIFS(Transactions!$F$7:$F$989,Transactions!$G$7:$G$989,A13,Transactions!$D$7:$D$989,"Expense"),0) -> 560.85 | I13: Attendance | J13: In-Season 2026
A14: Regionals | G14: =IFERROR(SUMIFS(Transactions!$F$7:$F$989,Transactions!$G$7:$G$989,A14,Transactions!$D$7:$D$989,"Expense"),0) -> 5965.16 | I14: Attendance | J14: In-Season 2026
A15: Retreat | G15: =IFERROR(SUMIFS(Transactions!$F$7:$F$989,Transactions!$G$7:$G$989,A15,Transactions!$D$7:$D$989,"Expense"),0) -> 9054.59 | I15: Attendance | J15: In-Season 2026
A16: Misc | G16: =IFERROR(SUMIFS(Transactions!$F$7:$F$989,Transactions!$G$7:$G$989,A16,Transactions!$D$7:$D$989,"Expense"),0) -> 0 | I16: Attendance | J16: In-Season 2026
A17: Nationals | G17: =IFERROR(SUMIFS(Transactions!$F$7:$F$989,Transactions!$G$7:$G$989,A17,Transactions!$D$7:$D$989,"Expense"),0) -> 7150 | I17: Attendance | J17: In-Season 2026
A18: Fan Stores | G18: =IFERROR(SUMIFS(Transactions!$F$7:$F$989,Transactions!$G$7:$G$989,A18,Transactions!$D$7:$D$989,"Expense"),0) -> 0
G19: =IFERROR(SUMIFS(Transactions!$F$7:$F$989,Transactions!$G$7:$G$989,A19,Transactions!$D$7:$D$989,"Expense"),0) -> 0
G20: =IFERROR(SUMIFS(Transactions!$F$7:$F$989,Transactions!$G$7:$G$989,A20,Transactions!$D$7:$D$989,"Expense"),0) -> 0
G21: =IFERROR(SUMIFS(Transactions!$F$7:$F$989,Transactions!$G$7:$G$989,A21,Transactions!$D$7:$D$989,"Expense"),0) -> 0
G22: =IFERROR(SUMIFS(Transactions!$F$7:$F$989,Transactions!$G$7:$G$989,A22,Transactions!$D$7:$D$989,"Expense"),0) -> 0
G23: =IFERROR(SUMIFS(Transactions!$F$7:$F$989,Transactions!$G$7:$G$989,A23,Transactions!$D$7:$D$989,"Expense"),0) -> 0
G24: =IFERROR(SUMIFS(Transactions!$F$7:$F$989,Transactions!$G$7:$G$989,A24,Transactions!$D$7:$D$989,"Expense"),0) -> 0
G25: =IFERROR(SUMIFS(Transactions!$F$7:$F$989,Transactions!$G$7:$G$989,A25,Transactions!$D$7:$D$989,"Expense"),0) -> 0
G26: =IFERROR(SUMIFS(Transactions!$F$7:$F$989,Transactions!$G$7:$G$989,A26,Transactions!$D$7:$D$989,"Expense"),0) -> 0
G27: =IFERROR(SUMIFS(Transactions!$F$7:$F$989,Transactions!$G$7:$G$989,A27,Transactions!$D$7:$D$989,"Expense"),0) -> 0
G28: =IFERROR(SUMIFS(Transactions!$F$7:$F$989,Transactions!$G$7:$G$989,A28,Transactions!$D$7:$D$989,"Expense"),0) -> 0
G29: =IFERROR(SUMIFS(Transactions!$F$7:$F$989,Transactions!$G$7:$G$989,A29,Transactions!$D$7:$D$989,"Expense"),0) -> 0
G30: =IFERROR(SUMIFS(Transactions!$F$7:$F$989,Transactions!$G$7:$G$989,A30,Transactions!$D$7:$D$989,"Expense"),0) -> 0
... G504: =IFERROR(SUMIFS(Transactions!$F$7:$F$989,Transactions!$G$7:$G$989,A504,Transactions!$D$7:$D$989,"Expense"),0) -> 0

Sheet Attendance
B1: ATTENDANCE TRACKER | AZ1: 57 | BA1: 58 | BB1: 59 | BC1: 60 | BD1: 61 | BY1: 62 | BZ1: 63 | CA1: 64 | CB1: 65 | CC1: 66 | CD1: 67 | CE1: 68 | CF1: 69 | CG1: 70 | CH1: 71 | CI1: 72 | CJ1: 73 | CK1: 74 | CL1: 75 | CM1: 76 | CN1: 77 | CO1: 78 | CP1: 79 | CQ1: 80 | CR1: 81 | CS1: 82 | CT1: 83 | CU1: 84 | CV1: 85 | CW1: 86 | CX1: 87 | CY1: 88 | CZ1: 89 | DA1: 90 | DB1: 91 | DC1: 92 | DD1: 93 | DE1: 94 | DF1: 95 | DG1: 96 | DH1: 97 | DI1: 98 | DJ1: 99
B2: =IF(AND(Transactions!$D7="Expense",Transactions!$G7<>""),"-> "&Transactions!$G7,"") -> -> PEC | C2: =IF(AND(Transactions!$D8="Expense",Transactions!$G8<>""),"-> "&Transactions!$G8,"") -> -> SFI | D2: =IF(AND(Transactions!$D9="Expense",Transactions!$G9<>""),"-> "&Transactions!$G9,"") | E2: =IF(AND(Transactions!$D10="Expense",Transactions!$G10<>""),"-> "&Transactions!$G10,"") | F2: =IF(AND(Transactions!$D11="Expense",Transactions!$G11<>""),"-> "&Transactions!$G11,"") | G2: =IF(AND(Transactions!$D12="Expense",Transactions!$G12<>""),"-> "&Transactions!$G12,"") -> -> May-July Fields | H2: =IF(AND(Transactions!$D13="Expense",Transactions!$G13<>""),"-> "&Transactions!$G13,"") -> -> PEC | I2: =IF(AND(Transactions!$D14="Expense",Transactions!$G14<>""),"-> "&Transactions!$G14,"") -> -> PEC | J2: =IF(AND(Transactions!$D15="Expense",Transactions!$G15<>""),"-> "&Transactions!$G15,"") | K2: =IF(AND(Transactions!$D16="Expense",Transactions!$G16<>""),"-> "&Transactions!$G16,"") | L2: =IF(AND(Transactions!$D17="Expense",Transactions!$G17<>""),"-> "&Transactions!$G17,"") -> -> PEC | M2: =IF(AND(Transactions!$D18="Expense",Transactions!$G18<>""),"-> "&Transactions!$G18,"") -> -> PEC | N2: =IF(AND(Transactions!$D19="Expense",Transactions!$G19<>""),"-> "&Transactions!$G19,"") | O2: =IF(AND(Transactions!$D20="Expense",Transactions!$G20<>""),"-> "&Transactions!$G20,"") -> -> PEC | P2: =IF(AND(Transactions!$D21="Expense",Transactions!$G21<>""),"-> "&Transactions!$G21,"") -> -> PEC | Q2: =IF(AND(Transactions!$D22="Expense",Transactions!$G22<>""),"-> "&Transactions!$G22,"") | R2: =IF(AND(Transactions!$D23="Expense",Transactions!$G23<>""),"-> "&Transactions!$G23,"") | S2: =IF(AND(Transactions!$D24="Expense",Transactions!$G24<>""),"-> "&Transactions!$G24,"") | T2: =IF(AND(Transactions!$D25="Expense",Transactions!$G25<>""),"-> "&Transactions!$G25,"") | U2: =IF(AND(Transactions!$D26="Expense",Transactions!$G26<>""),"-> "&Transactions!$G26,"") | V2: =IF(AND(Transactions!$D27="Expense",Transactions!$G27<>""),"-> "&Transactions!$G27,"") | W2: =IF(AND(Transactions!$D28="Expense",Transactions!$G28<>""),"-> "&Transactions!$G28,"") | X2: =IF(AND(Transactions!$D29="Expense",Transactions!$G29<>""),"-> "&Transactions!$G29,"") | Y2: =IF(AND(Transactions!$D30="Expense",Transactions!$G30<>""),"-> "&Transactions!$G30,"") | Z2: =IF(AND(Transactions!$D31="Expense",Transactions!$G31<>""),"-> "&Transactions!$G31,"") | AA2: =IF(AND(Transactions!$D32="Expense",Transactions!$G32<>""),"-> "&Transactions!$G32,"") | AB2: =IF(AND(Transactions!$D33="Expense",Transactions!$G33<>""),"-> "&Transactions!$G33,"") -> -> PEC | AC2: =IF(AND(Transactions!$D34="Expense",Transactions!$G34<>""),"-> "&Transactions!$G34,"") | AD2: =IF(AND(Transactions!$D35="Expense",Transactions!$G35<>""),"-> "&Transactions!$G35,"") -> -> ESC | AE2: =IF(AND(Transactions!$D36="Expense",Transactions!$G36<>""),"-> "&Transactions!$G36,"") | AF2: =IF(AND(Transactions!$D37="Expense",Transactions!$G37<>""),"-> "&Transactions!$G37,"") | AG2: =IF(AND(Transactions!$D38="Expense",Transactions!$G38<>""),"-> "&Transactions!$G38,"") | AH2: =IF(AND(Transactions!$D39="Expense",Transactions!$G39<>""),"-> "&Transactions!$G39,"") | AI2: =IF(AND(Transactions!$D40="Expense",Transactions!$G40<>""),"-> "&Transactions!$G40,"") -> -> SFI | AJ2: =IF(AND(Transactions!$D41="Expense",Transactions!$G41<>""),"-> "&Transactions!$G41,"") -> -> SFI | AK2: =IF(AND(Transactions!$D42="Expense",Transactions!$G42<>""),"-> "&Transactions!$G42,"") -> -> PEC | AL2: =IF(AND(Transactions!$D43="Expense",Transactions!$G43<>""),"-> "&Transactions!$G43,"") -> -> May-July Fields | AM2: =IF(AND(Transactions!$D44="Expense",Transactions!$G44<>""),"-> "&Transactions!$G44,"") | AN2: =IF(AND(Transactions!$D45="Expense",Transactions!$G45<>""),"-> "&Transactions!$G45,"") | AO2: =IF(AND(Transactions!$D46="Expense",Transactions!$G46<>""),"-> "&Transactions!$G46,"") | AP2: =IF(AND(Transactions!$D47="Expense",Transactions!$G47<>""),"-> "&Transactions!$G47,"") | AQ2: =IF(AND(Transactions!$D48="Expense",Transactions!$G48<>""),"-> "&Transactions!$G48,"") | AR2: =IF(AND(Transactions!$D49="Expense",Transactions!$G49<>""),"-> "&Transactions!$G49,"") -> -> Sectionals | AS2: =IF(AND(Transactions!$D50="Expense",Transactions!$G50<>""),"-> "&Transactions!$G50,"") -> -> ESC | AT2: =IF(AND(#REF!="Expense",#REF!<>""),"-> "&#REF!,"") -> #REF! | AU2: =IF(AND(Transactions!$D51="Expense",Transactions!$G51<>""),"-> "&Transactions!$G51,"") | AV2: =IF(AND(Transactions!$D53="Expense",Transactions!$G53<>""),"-> "&Transactions!$G53,"") -> -> ESC | AW2: {=IF(AND(INDEX(Transactions!$D:$D, COLUMN()+5)="Expense", INDEX(Transactions!$G:$G, COLUMN()+5)<>""), "-> "&INDEX(Transactions!$G:$G, COLUMN()+5), "")} | AX2: {=IF(AND(INDEX(Transactions!$D:$D, COLUMN()+5)="Expense", INDEX(Transactions!$G:$G, COLUMN()+5)<>""), "-> "&INDEX(Transactions!$G:$G, COLUMN()+5), "")} | AY2: {=IF(AND(INDEX(Transactions!$D:$D, COLUMN()+5)="Expense", INDEX(Transactions!$G:$G, COLUMN()+5)<>""), "-> "&INDEX(Transactions!$G:$G, COLUMN()+5), "")} -> -> PEC | AZ2: {=IF(AND(INDEX(Transactions!$D:$D, COLUMN()+5)="Expense", INDEX(Transactions!$G:$G, COLUMN()+5)<>""), "-> "&INDEX(Transactions!$G:$G, COLUMN()+5), "")} -> -> PEC | BA2: {=IF(AND(INDEX(Transactions!$D:$D, COLUMN()+5)="Expense", INDEX(Transactions!$G:$G, COLUMN()+5)<>""), "-> "&INDEX(Transactions!$G:$G, COLUMN()+5), "")} -> -> PEC | BB2: {=IF(AND(INDEX(Transactions!$D:$D, COLUMN()+5)="Expense", INDEX(Transactions!$G:$G, COLUMN()+5)<>""), "-> "&INDEX(Transactions!$G:$G, COLUMN()+5), "")} -> -> PEC | BC2: {=IF(AND(INDEX(Transactions!$D:$D, COLUMN()+5)="Expense", INDEX(Transactions!$G:$G, COLUMN()+5)<>""), "-> "&INDEX(Transactions!$G:$G, COLUMN()+5), "")} -> -> PEC | BD2: {=IF(AND(INDEX(Transactions!$D:$D, COLUMN()+5)="Expense", INDEX(Transactions!$G:$G, COLUMN()+5)<>""), "-> "&INDEX(Transactions!$G:$G, COLUMN()+5), "")} -> -> SFI | ... EE2: {=IF(AND(INDEX(Transactions!$D:$D, COLUMN()+5)="Expense", INDEX(Transactions!$G:$G, COLUMN()+5)<>""), "-> "&INDEX(Transactions!$G:$G, COLUMN()+5), "")}
A3: Player Name | B3: =IF(AND(Transactions!$D7="Expense",Transactions!$G7<>""),Transactions!$B7,"") -> PEC Bid Fee | C3: =IF(AND(Transactions!$D8="Expense",Transactions!$G8<>""),Transactions!$B8,"") -> SFI Bid Fee | D3: =IF(AND(Transactions!$D9="Expense",Transactions!$G9<>""),Transactions!$B9,"") | E3: =IF(AND(Transactions!$D10="Expense",Transactions!$G10<>""),Transactions!$B10,"") | F3: =IF(AND(Transactions!$D11="Expense",Transactions!$G11<>""),Transactions!$B11,"") | G3: =IF(AND(Transactions!$D12="Expense",Transactions!$G12<>""),Transactions!$B12,"") -> Wednesday Tryout Field | H3: =IF(AND(Transactions!$D13="Expense",Transactions!$G13<>""),Transactions!$B13,"") -> tshirts and spray paint | I3: =IF(AND(Transactions!$D14="Expense",Transactions!$G14<>""),Transactions!$B14,"") -> gso airport minivan | J3: =IF(AND(Transactions!$D15="Expense",Transactions!$G15<>""),Transactions!$B15,"") | K3: =IF(AND(Transactions!$D16="Expense",Transactions!$G16<>""),Transactions!$B16,"") | L3: =IF(AND(Transactions!$D17="Expense",Transactions!$G17<>""),Transactions!$B17,"") -> pec megavan | M3: =IF(AND(Transactions!$D18="Expense",Transactions!$G18<>""),Transactions!$B18,"") -> PEC Hotel | N3: =IF(AND(Transactions!$D19="Expense",Transactions!$G19<>""),Transactions!$B19,"") | O3: =IF(AND(Transactions!$D20="Expense",Transactions!$G20<>""),Transactions!$B20,"") -> gso minivan gas | P3: =IF(AND(Transactions!$D21="Expense",Transactions!$G21<>""),Transactions!$B21,"") -> Jake's Car Airport Parking | Q3: =IF(AND(Transactions!$D22="Expense",Transactions!$G22<>""),Transactions!$B22,"") | R3: =IF(AND(Transactions!$D23="Expense",Transactions!$G23<>""),Transactions!$B23,"") | S3: =IF(AND(Transactions!$D24="Expense",Transactions!$G24<>""),Transactions!$B24,"") | T3: =IF(AND(Transactions!$D25="Expense",Transactions!$G25<>""),Transactions!$B25,"") | U3: =IF(AND(Transactions!$D26="Expense",Transactions!$G26<>""),Transactions!$B26,"") | V3: =IF(AND(Transactions!$D27="Expense",Transactions!$G27<>""),Transactions!$B27,"") | W3: =IF(AND(Transactions!$D28="Expense",Transactions!$G28<>""),Transactions!$B28,"") | X3: =IF(AND(Transactions!$D29="Expense",Transactions!$G29<>""),Transactions!$B29,"") | Y3: =IF(AND(Transactions!$D30="Expense",Transactions!$G30<>""),Transactions!$B30,"") | Z3: =IF(AND(Transactions!$D31="Expense",Transactions!$G31<>""),Transactions!$B31,"") | AA3: =IF(AND(Transactions!$D32="Expense",Transactions!$G32<>""),Transactions!$B32,"") | AB3: =IF(AND(Transactions!$D33="Expense",Transactions!$G33<>""),Transactions!$B33,"") -> PEC Team Snacks | AC3: =IF(AND(Transactions!$D34="Expense",Transactions!$G34<>""),Transactions!$B34,"") | AD3: =IF(AND(Transactions!$D35="Expense",Transactions!$G35<>""),Transactions!$B35,"") -> ESC Bid Fee | AE3: =IF(AND(Transactions!$D36="Expense",Transactions!$G36<>""),Transactions!$B36,"") | AF3: =IF(AND(Transactions!$D37="Expense",Transactions!$G37<>""),Transactions!$B37,"") | AG3: =IF(AND(Transactions!$D38="Expense",Transactions!$G38<>""),Transactions!$B38,"") | AH3: =IF(AND(Transactions!$D39="Expense",Transactions!$G39<>""),Transactions!$B39,"") | AI3: =IF(AND(Transactions!$D40="Expense",Transactions!$G40<>""),Transactions!$B40,"") -> SFI Team snacks | AJ3: =IF(AND(Transactions!$D41="Expense",Transactions!$G41<>""),Transactions!$B41,"") -> SFI Hotels | AK3: =IF(AND(Transactions!$D42="Expense",Transactions!$G42<>""),Transactions!$B42,"") -> Mega Van Tolls | AL3: =IF(AND(Transactions!$D43="Expense",Transactions!$G43<>""),Transactions!$B43,"") -> Practice Fields thru July | AM3: =IF(AND(Transactions!$D44="Expense",Transactions!$G44<>""),Transactions!$B44,"") | AN3: =IF(AND(Transactions!$D45="Expense",Transactions!$G45<>""),Transactions!$B45,"") | AO3: =IF(AND(Transactions!$D46="Expense",Transactions!$G46<>""),Transactions!$B46,"") | AP3: =IF(AND(Transactions!$D47="Expense",Transactions!$G47<>""),Transactions!$B47,"") | AQ3: =IF(AND(Transactions!$D48="Expense",Transactions!$G48<>""),Transactions!$B48,"") | AR3: =IF(AND(Transactions!$D49="Expense",Transactions!$G49<>""),Transactions!$B49,"") -> Sectionals Bid Fee | AS3: =IF(AND(Transactions!$D50="Expense",Transactions!$G50<>""),Transactions!$B50,"") -> ESC Hotel | AT3: =IF(AND(#REF!="Expense",#REF!<>""),#REF!,"") -> #REF! | AU3: =IF(AND(Transactions!$D51="Expense",Transactions!$G51<>""),Transactions!$B51,"") | AV3: =IF(AND(Transactions!$D53="Expense",Transactions!$G53<>""),Transactions!$B53,"") -> ESC Team Snacks | AW3: {=IF(AND(INDEX(Transactions!$D:$D, 5 + COLUMN())="Expense", INDEX(Transactions!$G:$G, 5 + COLUMN())<>""), INDEX(Transactions!$B:$B, 5 + COLUMN()), "")} | AX3: {=IF(AND(INDEX(Transactions!$D:$D, 5 + COLUMN())="Expense", INDEX(Transactions!$G:$G, 5 + COLUMN())<>""), INDEX(Transactions!$B:$B, 5 + COLUMN()), "")} | AY3: {=IF(AND(INDEX(Transactions!$D:$D, 5 + COLUMN())="Expense", INDEX(Transactions!$G:$G, 5 + COLUMN())<>""), INDEX(Transactions!$B:$B, 5 + COLUMN()), "")} -> Sarah KH Car Credit | AZ3: {=IF(AND(INDEX(Transactions!$D:$D, 5 + COLUMN())="Expense", INDEX(Transactions!$G:$G, 5 + COLUMN())<>""), INDEX(Transactions!$B:$B, 5 + COLUMN()), "")} -> Sarah KH Car Credit | BA3: {=IF(AND(INDEX(Transactions!$D:$D, 5 + COLUMN())="Expense", INDEX(Transactions!$G:$G, 5 + COLUMN())<>""), INDEX(Transactions!$B:$B, 5 + COLUMN()), "")} -> Sarah KH Car Credit | BB3: {=IF(AND(INDEX(Transactions!$D:$D, 5 + COLUMN())="Expense", INDEX(Transactions!$G:$G, 5 + COLUMN())<>""), INDEX(Transactions!$B:$B, 5 + COLUMN()), "")} -> Sarah KH Car Credit | BC3: {=IF(AND(INDEX(Transactions!$D:$D, 5 + COLUMN())="Expense", INDEX(Transactions!$G:$G, 5 + COLUMN())<>""), INDEX(Transactions!$B:$B, 5 + COLUMN()), "")} -> PEC Pooled Car Fees | BD3: {=IF(AND(INDEX(Transactions!$D:$D, 5 + COLUMN())="Expense", INDEX(Transactions!$G:$G, 5 + COLUMN())<>""), INDEX(Transactions!$B:$B, 5 + COLUMN()), "")} -> SFI Pooled Car Fees | ... EE3: {=IF(AND(INDEX(Transactions!$D:$D, 5 + COLUMN())="Expense", INDEX(Transactions!$G:$G, 5 + COLUMN())<>""), INDEX(Transactions!$B:$B, 5 + COLUMN()), "")}
A4: Cost per Person ($) [auto] | B4: {=IF(B3="","",IFERROR(IF(INDEX(Events!$I$5:$I$204,MATCH(Transactions!$G7,Events!$A$5:$A$204,0))="Equal Split",Transactions!$F7/MAX(1,COUNTIFS('Access Codes'!$C$6:$C$105,"Player",'Access Codes'!$D$6:$D$105,"Active")),IF(INDEX(Events!$I$5:$I$204,MATCH(Transactions!$G7,Events!$A$5:$A$204,0))="Attendance",Transactions!$F7/MAX(1,COUNTIF(B$7:B$206,"1")),0)),0))} -> 36.8 | C4: {=IF(C3="","",IFERROR(IF(INDEX(Events!$I$5:$I$204,MATCH(Transactions!$G8,Events!$A$5:$A$204,0))="Equal Split",Transactions!$F8/MAX(1,COUNTIFS('Access Codes'!$C$6:$C$105,"Player",'Access Codes'!$D$6:$D$105,"Active")),IF(INDEX(Events!$I$5:$I$204,MATCH(Transactions!$G8,Events!$A$5:$A$204,0))="Attendance",Transactions!$F8/MAX(1,COUNTIF(C$7:C$206,"1")),0)),0))} -> 50 | D4: {=IF(D3="","",IFERROR(IF(INDEX(Events!$I$5:$I$204,MATCH(Transactions!$G9,Events!$A$5:$A$204,0))="Equal Split",Transactions!$F9/MAX(1,COUNTIFS('Access Codes'!$C$6:$C$105,"Player",'Access Codes'!$D$6:$D$105,"Active")),IF(INDEX(Events!$I$5:$I$204,MATCH(Transactions!$G9,Events!$A$5:$A$204,0))="Attendance",Transactions!$F9/MAX(1,COUNTIF(D$7:D$206,"1")),0)),0))} | E4: {=IF(E3="","",IFERROR(IF(INDEX(Events!$I$5:$I$204,MATCH(Transactions!$G10,Events!$A$5:$A$204,0))="Equal Split",Transactions!$F10/MAX(1,COUNTIFS('Access Codes'!$C$6:$C$105,"Player",'Access Codes'!$D$6:$D$105,"Active")),IF(INDEX(Events!$I$5:$I$204,MATCH(Transactions!$G10,Events!$A$5:$A$204,0))="Attendance",Transactions!$F10/MAX(1,COUNTIF(E$7:E$206,"1")),0)),0))} | F4: {=IF(F3="","",IFERROR(IF(INDEX(Events!$I$5:$I$204,MATCH(Transactions!$G11,Events!$A$5:$A$204,0))="Equal Split",Transactions!$F11/MAX(1,COUNTIFS('Access Codes'!$C$6:$C$105,"Player",'Access Codes'!$D$6:$D$105,"Active")),IF(INDEX(Events!$I$5:$I$204,MATCH(Transactions!$G11,Events!$A$5:$A$204,0))="Attendance",Transactions!$F11/MAX(1,COUNTIF(F$7:F$206,"1")),0)),0))} | G4: {=IF(G3="","",IFERROR(IF(INDEX(Events!$I$5:$I$204,MATCH(Transactions!$G12,Events!$A$5:$A$204,0))="Equal Split",Transactions!$F12/MAX(1,COUNTIFS('Access Codes'!$C$6:$C$105,"Player",'Access Codes'!$D$6:$D$105,"Active")),IF(INDEX(Events!$I$5:$I$204,MATCH(Transactions!$G12,Events!$A$5:$A$204,0))="Attendance",Transactions!$F12/MAX(1,COUNTIF(G$7:G$206,"1")),0)),0))} -> 2.3 | H4: {=IF(H3="","",IFERROR(IF(INDEX(Events!$I$5:$I$204,MATCH(Transactions!$G13,Events!$A$5:$A$204,0))="Equal Split",Transactions!$F13/MAX(1,COUNTIFS('Access Codes'!$C$6:$C$105,"Player",'Access Codes'!$D$6:$D$105,"Active")),IF(INDEX(Events!$I$5:$I$204,MATCH(Transactions!$G13,Events!$A$5:$A$204,0))="Attendance",Transactions!$F13/MAX(1,COUNTIF(H$7:H$206,"1")),0)),0))} -> 7.1419231 | I4: {=IF(I3="","",IFERROR(IF(INDEX(Events!$I$5:$I$204,MATCH(Transactions!$G14,Events!$A$5:$A$204,0))="Equal Split",Transactions!$F14/MAX(1,COUNTIFS('Access Codes'!$C$6:$C$105,"Player",'Access Codes'!$D$6:$D$105,"Active")),IF(INDEX(Events!$I$5:$I$204,MATCH(Transactions!$G14,Events!$A$5:$A$204,0))="Attendance",Transactions!$F14/MAX(1,COUNTIF(I$7:I$206,"1")),0)),0))} -> 38.073333 | J4: {=IF(J3="","",IFERROR(IF(INDEX(Events!$I$5:$I$204,MATCH(Transactions!$G15,Events!$A$5:$A$204,0))="Equal Split",Transactions!$F15/MAX(1,COUNTIFS('Access Codes'!$C$6:$C$105,"Player",'Access Codes'!$D$6:$D$105,"Active")),IF(INDEX(Events!$I$5:$I$204,MATCH(Transactions!$G15,Events!$A$5:$A$204,0))="Attendance",Transactions!$F15/MAX(1,COUNTIF(J$7:J$206,"1")),0)),0))} | K4: {=IF(K3="","",IFERROR(IF(INDEX(Events!$I$5:$I$204,MATCH(Transactions!$G16,Events!$A$5:$A$204,0))="Equal Split",Transactions!$F16/MAX(1,COUNTIFS('Access Codes'!$C$6:$C$105,"Player",'Access Codes'!$D$6:$D$105,"Active")),IF(INDEX(Events!$I$5:$I$204,MATCH(Transactions!$G16,Events!$A$5:$A$204,0))="Attendance",Transactions!$F16/MAX(1,COUNTIF(K$7:K$206,"1")),0)),0))} | L4: {=IF(L3="","",IFERROR(IF(INDEX(Events!$I$5:$I$204,MATCH(Transactions!$G17,Events!$A$5:$A$204,0))="Equal Split",Transactions!$F17/MAX(1,COUNTIFS('Access Codes'!$C$6:$C$105,"Player",'Access Codes'!$D$6:$D$105,"Active")),IF(INDEX(Events!$I$5:$I$204,MATCH(Transactions!$G17,Events!$A$5:$A$204,0))="Attendance",Transactions!$F17/MAX(1,COUNTIF(L$7:L$206,"1")),0)),0))} -> 0 | M4: {=IF(M3="","",IFERROR(IF(INDEX(Events!$I$5:$I$204,MATCH(Transactions!$G18,Events!$A$5:$A$204,0))="Equal Split",Transactions!$F18/MAX(1,COUNTIFS('Access Codes'!$C$6:$C$105,"Player",'Access Codes'!$D$6:$D$105,"Active")),IF(INDEX(Events!$I$5:$I$204,MATCH(Transactions!$G18,Events!$A$5:$A$204,0))="Attendance",Transactions!$F18/MAX(1,COUNTIF(M$7:M$206,"1")),0)),0))} -> 129.17 | N4: {=IF(N3="","",IFERROR(IF(INDEX(Events!$I$5:$I$204,MATCH(Transactions!$G19,Events!$A$5:$A$204,0))="Equal Split",Transactions!$F19/MAX(1,COUNTIFS('Access Codes'!$C$6:$C$105,"Player",'Access Codes'!$D$6:$D$105,"Active")),IF(INDEX(Events!$I$5:$I$204,MATCH(Transactions!$G19,Events!$A$5:$A$204,0))="Attendance",Transactions!$F19/MAX(1,COUNTIF(N$7:N$206,"1")),0)),0))} | O4: {=IF(O3="","",IFERROR(IF(INDEX(Events!$I$5:$I$204,MATCH(Transactions!$G20,Events!$A$5:$A$204,0))="Equal Split",Transactions!$F20/MAX(1,COUNTIFS('Access Codes'!$C$6:$C$105,"Player",'Access Codes'!$D$6:$D$105,"Active")),IF(INDEX(Events!$I$5:$I$204,MATCH(Transactions!$G20,Events!$A$5:$A$204,0))="Attendance",Transactions!$F20/MAX(1,COUNTIF(O$7:O$206,"1")),0)),0))} -> 2.5433333 | P4: {=IF(P3="","",IFERROR(IF(INDEX(Events!$I$5:$I$204,MATCH(Transactions!$G21,Events!$A$5:$A$204,0))="Equal Split",Transactions!$F21/MAX(1,COUNTIFS('Access Codes'!$C$6:$C$105,"Player",'Access Codes'!$D$6:$D$105,"Active")),IF(INDEX(Events!$I$5:$I$204,MATCH(Transactions!$G21,Events!$A$5:$A$204,0))="Attendance",Transactions!$F21/MAX(1,COUNTIF(P$7:P$206,"1")),0)),0))} -> 20.91 | Q4: {=IF(Q3="","",IFERROR(IF(INDEX(Events!$I$5:$I$204,MATCH(Transactions!$G22,Events!$A$5:$A$204,0))="Equal Split",Transactions!$F22/MAX(1,COUNTIFS('Access Codes'!$C$6:$C$105,"Player",'Access Codes'!$D$6:$D$105,"Active")),IF(INDEX(Events!$I$5:$I$204,MATCH(Transactions!$G22,Events!$A$5:$A$204,0))="Attendance",Transactions!$F22/MAX(1,COUNTIF(Q$7:Q$206,"1")),0)),0))} | R4: {=IF(R3="","",IFERROR(IF(INDEX(Events!$I$5:$I$204,MATCH(Transactions!$G23,Events!$A$5:$A$204,0))="Equal Split",Transactions!$F23/MAX(1,COUNTIFS('Access Codes'!$C$6:$C$105,"Player",'Access Codes'!$D$6:$D$105,"Active")),IF(INDEX(Events!$I$5:$I$204,MATCH(Transactions!$G23,Events!$A$5:$A$204,0))="Attendance",Transactions!$F23/MAX(1,COUNTIF(R$7:R$206,"1")),0)),0))} | S4: {=IF(S3="","",IFERROR(IF(INDEX(Events!$I$5:$I$204,MATCH(Transactions!$G24,Events!$A$5:$A$204,0))="Equal Split",Transactions!$F24/MAX(1,COUNTIFS('Access Codes'!$C$6:$C$105,"Player",'Access Codes'!$D$6:$D$105,"Active")),IF(INDEX(Events!$I$5:$I$204,MATCH(Transactions!$G24,Events!$A$5:$A$204,0))="Attendance",Transactions!$F24/MAX(1,COUNTIF(S$7:S$206,"1")),0)),0))} | T4: {=IF(T3="","",IFERROR(IF(INDEX(Events!$I$5:$I$204,MATCH(Transactions!$G25,Events!$A$5:$A$204,0))="Equal Split",Transactions!$F25/MAX(1,COUNTIFS('Access Codes'!$C$6:$C$105,"Player",'Access Codes'!$D$6:$D$105,"Active")),IF(INDEX(Events!$I$5:$I$204,MATCH(Transactions!$G25,Events!$A$5:$A$204,0))="Attendance",Transactions!$F25/MAX(1,COUNTIF(T$7:T$206,"1")),0)),0))} | U4: {=IF(U3="","",IFERROR(IF(INDEX(Events!$I$5:$I$204,MATCH(Transactions!$G26,Events!$A$5:$A$204,0))="Equal Split",Transactions!$F26/MAX(1,COUNTIFS('Access Codes'!$C$6:$C$105,"Player",'Access Codes'!$D$6:$D$105,"Active")),IF(INDEX(Events!$I$5:$I$204,MATCH(Transactions!$G26,Events!$A$5:$A$204,0))="Attendance",Transactions!$F26/MAX(1,COUNTIF(U$7:U$206,"1")),0)),0))} | V4: {=IF(V3="","",IFERROR(IF(INDEX(Events!$I$5:$I$204,MATCH(Transactions!$G27,Events!$A$5:$A$204,0))="Equal Split",Transactions!$F27/MAX(1,COUNTIFS('Access Codes'!$C$6:$C$105,"Player",'Access Codes'!$D$6:$D$105,"Active")),IF(INDEX(Events!$I$5:$I$204,MATCH(Transactions!$G27,Events!$A$5:$A$204,0))="Attendance",Transactions!$F27/MAX(1,COUNTIF(V$7:V$206,"1")),0)),0))} | W4: {=IF(W3="","",IFERROR(IF(INDEX(Events!$I$5:$I$204,MATCH(Transactions!$G28,Events!$A$5:$A$204,0))="Equal Split",Transactions!$F28/MAX(1,COUNTIFS('Access Codes'!$C$6:$C$105,"Player",'Access Codes'!$D$6:$D$105,"Active")),IF(INDEX(Events!$I$5:$I$204,MATCH(Transactions!$G28,Events!$A$5:$A$204,0))="Attendance",Transactions!$F28/MAX(1,COUNTIF(W$7:W$206,"1")),0)),0))} | X4: {=IF(X3="","",IFERROR(IF(INDEX(Events!$I$5:$I$204,MATCH(Transactions!$G29,Events!$A$5:$A$204,0))="Equal Split",Transactions!$F29/MAX(1,COUNTIFS('Access Codes'!$C$6:$C$105,"Player",'Access Codes'!$D$6:$D$105,"Active")),IF(INDEX(Events!$I$5:$I$204,MATCH(Transactions!$G29,Events!$A$5:$A$204,0))="Attendance",Transactions!$F29/MAX(1,COUNTIF(X$7:X$206,"1")),0)),0))} | Y4: {=IF(Y3="","",IFERROR(IF(INDEX(Events!$I$5:$I$204,MATCH(Transactions!$G30,Events!$A$5:$A$204,0))="Equal Split",Transactions!$F30/MAX(1,COUNTIFS('Access Codes'!$C$6:$C$105,"Player",'Access Codes'!$D$6:$D$105,"Active")),IF(INDEX(Events!$I$5:$I$204,MATCH(Transactions!$G30,Events!$A$5:$A$204,0))="Attendance",Transactions!$F30/MAX(1,COUNTIF(Y$7:Y$206,"1")),0)),0))} | Z4: {=IF(Z3="","",IFERROR(IF(INDEX(Events!$I$5:$I$204,MATCH(Transactions!$G31,Events!$A$5:$A$204,0))="Equal Split",Transactions!$F31/MAX(1,COUNTIFS('Access Codes'!$C$6:$C$105,"Player",'Access Codes'!$D$6:$D$105,"Active")),IF(INDEX(Events!$I$5:$I$204,MATCH(Transactions!$G31,Events!$A$5:$A$204,0))="Attendance",Transactions!$F31/MAX(1,COUNTIF(Z$7:Z$206,"1")),0)),0))} | AA4: {=IF(AA3="","",IFERROR(IF(INDEX(Events!$I$5:$I$204,MATCH(Transactions!$G32,Events!$A$5:$A$204,0))="Equal Split",Transactions!$F32/MAX(1,COUNTIFS('Access Codes'!$C$6:$C$105,"Player",'Access Codes'!$D$6:$D$105,"Active")),IF(INDEX(Events!$I$5:$I$204,MATCH(Transactions!$G32,Events!$A$5:$A$204,0))="Attendance",Transactions!$F32/MAX(1,COUNTIF(AA$7:AA$206,"1")),0)),0))} | AB4: {=IF(AB3="","",IFERROR(IF(INDEX(Events!$I$5:$I$204,MATCH(Transactions!$G33,Events!$A$5:$A$204,0))="Equal Split",Transactions!$F33/MAX(1,COUNTIFS('Access Codes'!$C$6:$C$105,"Player",'Access Codes'!$D$6:$D$105,"Active")),IF(INDEX(Events!$I$5:$I$204,MATCH(Transactions!$G33,Events!$A$5:$A$204,0))="Attendance",Transactions!$F33/MAX(1,COUNTIF(AB$7:AB$206,"1")),0)),0))} -> 7.2442857 | AC4: {=IF(AC3="","",IFERROR(IF(INDEX(Events!$I$5:$I$204,MATCH(Transactions!$G34,Events!$A$5:$A$204,0))="Equal Split",Transactions!$F34/MAX(1,COUNTIFS('Access Codes'!$C$6:$C$105,"Player",'Access Codes'!$D$6:$D$105,"Active")),IF(INDEX(Events!$I$5:$I$204,MATCH(Transactions!$G34,Events!$A$5:$A$204,0))="Attendance",Transactions!$F34/MAX(1,COUNTIF(AC$7:AC$206,"1")),0)),0))} | AD4: {=IF(AD3="","",IFERROR(IF(INDEX(Events!$I$5:$I$204,MATCH(Transactions!$G35,Events!$A$5:$A$204,0))="Equal Split",Transactions!$F35/MAX(1,COUNTIFS('Access Codes'!$C$6:$C$105,"Player",'Access Codes'!$D$6:$D$105,"Active")),IF(INDEX(Events!$I$5:$I$204,MATCH(Transactions!$G35,Events!$A$5:$A$204,0))="Attendance",Transactions!$F35/MAX(1,COUNTIF(AD$7:AD$206,"1")),0)),0))} -> 41.666667 | AE4: {=IF(AE3="","",IFERROR(IF(INDEX(Events!$I$5:$I$204,MATCH(Transactions!$G36,Events!$A$5:$A$204,0))="Equal Split",Transactions!$F36/MAX(1,COUNTIFS('Access Codes'!$C$6:$C$105,"Player",'Access Codes'!$D$6:$D$105,"Active")),IF(INDEX(Events!$I$5:$I$204,MATCH(Transactions!$G36,Events!$A$5:$A$204,0))="Attendance",Transactions!$F36/MAX(1,COUNTIF(AE$7:AE$206,"1")),0)),0))} | AF4: {=IF(AF3="","",IFERROR(IF(INDEX(Events!$I$5:$I$204,MATCH(Transactions!$G37,Events!$A$5:$A$204,0))="Equal Split",Transactions!$F37/MAX(1,COUNTIFS('Access Codes'!$C$6:$C$105,"Player",'Access Codes'!$D$6:$D$105,"Active")),IF(INDEX(Events!$I$5:$I$204,MATCH(Transactions!$G37,Events!$A$5:$A$204,0))="Attendance",Transactions!$F37/MAX(1,COUNTIF(AF$7:AF$206,"1")),0)),0))} | AG4: {=IF(AG3="","",IFERROR(IF(INDEX(Events!$I$5:$I$204,MATCH(Transactions!$G38,Events!$A$5:$A$204,0))="Equal Split",Transactions!$F38/MAX(1,COUNTIFS('Access Codes'!$C$6:$C$105,"Player",'Access Codes'!$D$6:$D$105,"Active")),IF(INDEX(Events!$I$5:$I$204,MATCH(Transactions!$G38,Events!$A$5:$A$204,0))="Attendance",Transactions!$F38/MAX(1,COUNTIF(AG$7:AG$206,"1")),0)),0))} | AH4: {=IF(AH3="","",IFERROR(IF(INDEX(Events!$I$5:$I$204,MATCH(Transactions!$G39,Events!$A$5:$A$204,0))="Equal Split",Transactions!$F39/MAX(1,COUNTIFS('Access Codes'!$C$6:$C$105,"Player",'Access Codes'!$D$6:$D$105,"Active")),IF(INDEX(Events!$I$5:$I$204,MATCH(Transactions!$G39,Events!$A$5:$A$204,0))="Attendance",Transactions!$F39/MAX(1,COUNTIF(AH$7:AH$206,"1")),0)),0))} | AI4: {=IF(AI3="","",IFERROR(IF(INDEX(Events!$I$5:$I$204,MATCH(Transactions!$G40,Events!$A$5:$A$204,0))="Equal Split",Transactions!$F40/MAX(1,COUNTIFS('Access Codes'!$C$6:$C$105,"Player",'Access Codes'!$D$6:$D$105,"Active")),IF(INDEX(Events!$I$5:$I$204,MATCH(Transactions!$G40,Events!$A$5:$A$204,0))="Attendance",Transactions!$F40/MAX(1,COUNTIF(AI$7:AI$206,"1")),0)),0))} -> 12.64125 | AJ4: {=IF(AJ3="","",IFERROR(IF(INDEX(Events!$I$5:$I$204,MATCH(Transactions!$G41,Events!$A$5:$A$204,0))="Equal Split",Transactions!$F41/MAX(1,COUNTIFS('Access Codes'!$C$6:$C$105,"Player",'Access Codes'!$D$6:$D$105,"Active")),IF(INDEX(Events!$I$5:$I$204,MATCH(Transactions!$G41,Events!$A$5:$A$204,0))="Attendance",Transactions!$F41/MAX(1,COUNTIF(AJ$7:AJ$206,"1")),0)),0))} -> 99.55 | AK4: {=IF(AK3="","",IFERROR(IF(INDEX(Events!$I$5:$I$204,MATCH(Transactions!$G42,Events!$A$5:$A$204,0))="Equal Split",Transactions!$F42/MAX(1,COUNTIFS('Access Codes'!$C$6:$C$105,"Player",'Access Codes'!$D$6:$D$105,"Active")),IF(INDEX(Events!$I$5:$I$204,MATCH(Transactions!$G42,Events!$A$5:$A$204,0))="Attendance",Transactions!$F42/MAX(1,COUNTIF(AK$7:AK$206,"1")),0)),0))} -> 2.4927273 | AL4: {=IF(AL3="","",IFERROR(IF(INDEX(Events!$I$5:$I$204,MATCH(INDEX(Transactions!$G:$G, COLUMN()+5),Events!$A$5:$A$204,0))="Equal Split",INDEX(Transactions!$F:$F, COLUMN()+5)/MAX(1,COUNTIFS('Access Codes'!$C$6:$C$105,"Player",'Access Codes'!$D$6:$D$105,"Active")),IF(INDEX(Events!$I$5:$I$204,MATCH(INDEX(Transactions!$G:$G, COLUMN()+5),Events!$A$5:$A$204,0))="Attendance",INDEX(Transactions!$F:$F, COLUMN()+5)/MAX(1,COUNTIF(INDIRECT(SUBSTITUTE(ADDRESS(1, COLUMN(), 4), "1", "") & "7:" & SUBSTITUTE(ADDRESS(1, COLUMN(), 4), "1", "") & "206"),"1")),0)),0))} -> 75.233333 | AM4: {=IF(AM3="","",IFERROR(IF(INDEX(Events!$I$5:$I$204,MATCH(INDEX(Transactions!$G:$G, COLUMN()+5),Events!$A$5:$A$204,0))="Equal Split",INDEX(Transactions!$F:$F, COLUMN()+5)/MAX(1,COUNTIFS('Access Codes'!$C$6:$C$105,"Player",'Access Codes'!$D$6:$D$105,"Active")),IF(INDEX(Events!$I$5:$I$204,MATCH(INDEX(Transactions!$G:$G, COLUMN()+5),Events!$A$5:$A$204,0))="Attendance",INDEX(Transactions!$F:$F, COLUMN()+5)/MAX(1,COUNTIF(INDIRECT(SUBSTITUTE(ADDRESS(1, COLUMN(), 4), "1", "") & "7:" & SUBSTITUTE(ADDRESS(1, COLUMN(), 4), "1", "") & "206"),"1")),0)),0))} | AN4: {=IF(AN3="","",IFERROR(IF(INDEX(Events!$I$5:$I$204,MATCH(INDEX(Transactions!$G:$G, COLUMN()+5),Events!$A$5:$A$204,0))="Equal Split",INDEX(Transactions!$F:$F, COLUMN()+5)/MAX(1,COUNTIFS('Access Codes'!$C$6:$C$105,"Player",'Access Codes'!$D$6:$D$105,"Active")),IF(INDEX(Events!$I$5:$I$204,MATCH(INDEX(Transactions!$G:$G, COLUMN()+5),Events!$A$5:$A$204,0))="Attendance",INDEX(Transactions!$F:$F, COLUMN()+5)/MAX(1,COUNTIF(INDIRECT(SUBSTITUTE(ADDRESS(1, COLUMN(), 4), "1", "") & "7:" & SUBSTITUTE(ADDRESS(1, COLUMN(), 4), "1", "") & "206"),"1")),0)),0))} | AO4: {=IF(AO3="","",IFERROR(IF(INDEX(Events!$I$5:$I$204,MATCH(INDEX(Transactions!$G:$G, COLUMN()+5),Events!$A$5:$A$204,0))="Equal Split",INDEX(Transactions!$F:$F, COLUMN()+5)/MAX(1,COUNTIFS('Access Codes'!$C$6:$C$105,"Player",'Access Codes'!$D$6:$D$105,"Active")),IF(INDEX(Events!$I$5:$I$204,MATCH(INDEX(Transactions!$G:$G, COLUMN()+5),Events!$A$5:$A$204,0))="Attendance",INDEX(Transactions!$F:$F, COLUMN()+5)/MAX(1,COUNTIF(INDIRECT(SUBSTITUTE(ADDRESS(1, COLUMN(), 4), "1", "") & "7:" & SUBSTITUTE(ADDRESS(1, COLUMN(), 4), "1", "") & "206"),"1")),0)),0))} | AP4: {=IF(AP3="","",IFERROR(IF(INDEX(Events!$I$5:$I$204,MATCH(INDEX(Transactions!$G:$G, COLUMN()+5),Events!$A$5:$A$204,0))="Equal Split",INDEX(Transactions!$F:$F, COLUMN()+5)/MAX(1,COUNTIFS('Access Codes'!$C$6:$C$105,"Player",'Access Codes'!$D$6:$D$105,"Active")),IF(INDEX(Events!$I$5:$I$204,MATCH(INDEX(Transactions!$G:$G, COLUMN()+5),Events!$A$5:$A$204,0))="Attendance",INDEX(Transactions!$F:$F, COLUMN()+5)/MAX(1,COUNTIF(INDIRECT(SUBSTITUTE(ADDRESS(1, COLUMN(), 4), "1", "") & "7:" & SUBSTITUTE(ADDRESS(1, COLUMN(), 4), "1", "") & "206"),"1")),0)),0))} | AQ4: {=IF(AQ3="","",IFERROR(IF(INDEX(Events!$I$5:$I$204,MATCH(INDEX(Transactions!$G:$G, COLUMN()+5),Events!$A$5:$A$204,0))="Equal Split",INDEX(Transactions!$F:$F, COLUMN()+5)/MAX(1,COUNTIFS('Access Codes'!$C$6:$C$105,"Player",'Access Codes'!$D$6:$D$105,"Active")),IF(INDEX(Events!$I$5:$I$204,MATCH(INDEX(Transactions!$G:$G, COLUMN()+5),Events!$A$5:$A$204,0))="Attendance",INDEX(Transactions!$F:$F, COLUMN()+5)/MAX(1,COUNTIF(INDIRECT(SUBSTITUTE(ADDRESS(1, COLUMN(), 4), "1", "") & "7:" & SUBSTITUTE(ADDRESS(1, COLUMN(), 4), "1", "") & "206"),"1")),0)),0))} | AR4: {=IF(AR3="","",IFERROR(IF(INDEX(Events!$I$5:$I$204,MATCH(INDEX(Transactions!$G:$G, COLUMN()+5),Events!$A$5:$A$204,0))="Equal Split",INDEX(Transactions!$F:$F, COLUMN()+5)/MAX(1,COUNTIFS('Access Codes'!$C$6:$C$105,"Player",'Access Codes'!$D$6:$D$105,"Active")),IF(INDEX(Events!$I$5:$I$204,MATCH(INDEX(Transactions!$G:$G, COLUMN()+5),Events!$A$5:$A$204,0))="Attendance",INDEX(Transactions!$F:$F, COLUMN()+5)/MAX(1,COUNTIF(INDIRECT(SUBSTITUTE(ADDRESS(1, COLUMN(), 4), "1", "") & "7:" & SUBSTITUTE(ADDRESS(1, COLUMN(), 4), "1", "") & "206"),"1")),0)),0))} -> 22 | AS4: {=IF(AS3="","",IFERROR(IF(INDEX(Events!$I$5:$I$204,MATCH(INDEX(Transactions!$G:$G, COLUMN()+5),Events!$A$5:$A$204,0))="Equal Split",INDEX(Transactions!$F:$F, COLUMN()+5)/MAX(1,COUNTIFS('Access Codes'!$C$6:$C$105,"Player",'Access Codes'!$D$6:$D$105,"Active")),IF(INDEX(Events!$I$5:$I$204,MATCH(INDEX(Transactions!$G:$G, COLUMN()+5),Events!$A$5:$A$204,0))="Attendance",INDEX(Transactions!$F:$F, COLUMN()+5)/MAX(1,COUNTIF(INDIRECT(SUBSTITUTE(ADDRESS(1, COLUMN(), 4), "1", "") & "7:" & SUBSTITUTE(ADDRESS(1, COLUMN(), 4), "1", "") & "206"),"1")),0)),0))} -> 121.0848 | ... EE4: {=IF(EE3="","",IFERROR(IF(INDEX(Events!$I$5:$I$204,MATCH(INDEX(Transactions!$G:$G, COLUMN()+5),Events!$A$5:$A$204,0))="Equal Split",INDEX(Transactions!$F:$F, COLUMN()+5)/MAX(1,COUNTIFS('Access Codes'!$C$6:$C$105,"Player",'Access Codes'!$D$6:$D$105,"Active")),IF(INDEX(Events!$I$5:$I$204,MATCH(INDEX(Transactions!$G:$G, COLUMN()+5),Events!$A$5:$A$204,0))="Attendance",INDEX(Transactions!$F:$F, COLUMN()+5)/MAX(1,COUNTIF(INDIRECT(SUBSTITUTE(ADDRESS(1, COLUMN(), 4), "1", "") & "7:" & SUBSTITUTE(ADDRESS(1, COLUMN(), 4), "1", "") & "206"),"1")),0)),0))}
A5: Total Attendees | B5: =COUNTIF(B7:B206,"1") -> 25 | C5: =COUNTIF(C7:C206,"1") -> 23 | D5: =COUNTIF(D7:D206,"1") -> 0 | E5: =COUNTIF(E7:E206,"1") -> 0 | F5: =COUNTIF(F7:F206,"1") -> 0 | G5: =COUNTIF(G7:G206,"1") -> 30 | H5: =COUNTIF(H7:H206,"1") -> 26 | I5: =COUNTIF(I7:I206,"1") -> 6 | ... EE5: =COUNTIF(EE7:EE206,"1") -> 0
A6: Total Cost ($) | B6: =B4*B5 -> 920 | C6: =C4*C5 -> 1150 | D6: =D4*D5 -> 0 | E6: =E4*E5 -> 0 | F6: =F4*F5 -> 0 | G6: =G4*G5 -> 69 | H6: =H4*H5 -> 185.69 | I6: =I4*I5 -> 228.44 | ... EE6: =EE4*EE5 -> 0
A7: =IF(Roster!$A$5<>"",Roster!$A$5,"") -> At | B7: 1 | C7: 1 | G7: 1 | H7: 1 | I7: 1 | J7: 1 | L7: 0 | M7: 1 | O7: 1 | P7: 1 | AB7: 1 | AD7: 1 | AI7: 1 | AJ7: 1 | AK7: 0 | AL7: 1 | AR7: 1 | AS7: 1 | AV7: 1 | BC7: 0 | BD7: 1 | BE7: 1 | BW7: 1 | BX7: 0 | BY7: 0 | BZ7: 0 | CA7: 0 | CI7: 1 | CJ7: 1 | CK7: 1 | CL7: 0 | CQ7: 1 | CY7: 1
A8: =IF(Roster!$A$6<>"",Roster!$A$6,"") -> Alex Warrington | B8: 1 | C8: 1 | G8: 1 | H8: 1 | I8: 0 | J8: 1 | L8: 0 | M8: 1 | O8: 0 | P8: 0 | AB8: 0 | AD8: 1 | AI8: 0 | AJ8: 1 | AK8: 0 | AL8: 1 | AR8: 1 | AS8: 1 | AV8: 0 | BC8: 1 | BD8: 1 | BE8: 1 | BW8: 1 | BX8: 0 | BY8: 0 | BZ8: 0 | CA8: 0 | CI8: 1 | CJ8: 0 | CK8: 1 | CL8: 0 | CQ8: 1 | CY8: 1
A9: =IF(Roster!$A$7<>"",Roster!$A$7,"") -> Chris Wohl | B9: 1 | C9: 1 | G9: 1 | H9: 1 | I9: 0 | J9: 1 | L9: 1 | M9: 1 | O9: 0 | P9: 0 | AB9: 1 | AD9: 1 | AI9: 1 | AJ9: 1 | AK9: 1 | AL9: 1 | AR9: 1 | AS9: 1 | AV9: 1 | BC9: 0 | BD9: 1 | BE9: 1 | BW9: 1 | BX9: 0 | BY9: 0 | BZ9: 0 | CA9: 0 | CI9: 1 | CJ9: 1 | CK9: 1 | CL9: 1 | CQ9: 1 | CY9: 1
A10: =IF(Roster!$A$8<>"",Roster!$A$8,"") -> Darra Reppermund | B10: 1 | C10: 1 | G10: 1 | H10: 1 | I10: 0 | J10: 1 | L10: 0 | M10: 1 | O10: 0 | P10: 0 | AB10: 1 | AD10: 1 | AI10: 1 | AJ10: 0 | AK10: 0 | AL10: 1 | AR10: 1 | AS10: 1 | AV10: 1 | BC10: 1 | BD10: 0 | BE10: 1 | BW10: 1 | BX10: 0 | BY10: 0 | BZ10: 0 | CA10: 0 | CI10: 1 | CJ10: 1 | CK10: 1 | CL10: 0 | CQ10: 1 | CY10: 1
A11: =IF(Roster!$A$9<>"",Roster!$A$9,"") -> Dylan Best | B11: 1 | C11: 1 | G11: 1 | H11: 1 | I11: 1 | J11: 1 | L11: 0 | M11: 1 | O11: 1 | P11: 1 | AB11: 1 | AD11: 1 | AI11: 1 | AJ11: 1 | AK11: 0 | AL11: 1 | AR11: 1 | AS11: 1 | AV11: 1 | BC11: 0 | BD11: 1 | BE11: X | BW11: 1 | BX11: 0 | BY11: 0 | BZ11: 0 | CA11: 0 | CI11: 1 | CJ11: 1 | CK11: 1 | CL11: 0 | CQ11: 1 | CY11: 1
A12: =IF(Roster!$A$10<>"",Roster!$A$10,"") -> Griffin O'Neal-Freeman | B12: 1 | C12: 1 | G12: 1 | H12: 1 | I12: 0 | J12: 1 | L12: 1 | M12: 1 | O12: 0 | P12: 0 | AB12: 1 | AD12: 1 | AI12: 1 | AJ12: 1 | AK12: 1 | AL12: 1 | AR12: 1 | AS12: 1 | AV12: 1 | BC12: 0 | BD12: X | BE12: 1 | BW12: 0 | BX12: 1 | BY12: 0 | BZ12: 0 | CA12: 0 | CI12: 1 | CJ12: 1 | CK12: 1 | CL12: 1 | CQ12: 1 | CY12: 1
A13: =IF(Roster!$A$11<>"",Roster!$A$11,"") -> Haley Young | B13: 1 | C13: 1 | G13: 1 | H13: 1 | I13: 0 | J13: 1 | L13: 0 | M13: 1 | O13: 0 | P13: 0 | AB13: 0 | AD13: 1 | AI13: 0 | AJ13: 1 | AK13: 0 | AL13: 1 | AR13: 1 | AS13: 1 | AV13: 1 | BC13: 1 | BD13: X | BE13: 1 | BW13: 0 | BX13: 1 | BY13: 0 | BZ13: 0 | CA13: 0 | CI13: 1 | CJ13: 0 | CK13: 1 | CL13: 0 | CQ13: 1 | CY13: 1
A14: =IF(Roster!$A$12<>"",Roster!$A$12,"") -> Harry Park | B14: 1 | C14: 1 | G14: 1 | H14: 1 | I14: 0 | J14: 1 | L14: 1 | M14: 1 | O14: 0 | P14: 0 | AB14: 1 | AD14: 1 | AI14: 1 | AJ14: 1 | AK14: 1 | AL14: 1 | AR14: 1 | AS14: 1 | AV14: 1 | BC14: 0 | BD14: 1 | BE14: X | BW14: 0 | BX14: 0 | BY14: 0 | BZ14: 0 | CA14: 0 | CI14: 1 | CJ14: 1 | CK14: 1 | CL14: 1 | CQ14: 1 | CY14: 1
A15: =IF(Roster!$A$13<>"",Roster!$A$13,"") -> Ian Piper | B15: X | C15: 1 | G15: 1 | H15: 1 | I15: 0 | J15: 1 | L15: 1 | M15: 1 | O15: 0 | P15: 0 | AB15: 1 | AD15: 1 | AI15: 1 | AJ15: 1 | AK15: 1 | AL15: 1 | AR15: 1 | AS15: 1 | AV15: 1 | BC15: 0 | BD15: 1 | BE15: 1 | BW15: 0 | BX15: 1 | BY15: 0 | BZ15: 0 | CA15: 0 | CI15: 1 | CJ15: 1 | CK15: 1 | CL15: 1 | CQ15: 1 | CY15: 1
A16: =IF(Roster!$A$14<>"",Roster!$A$14,"") -> Jake Murray | B16: 1 | C16: 1 | G16: 1 | H16: 1 | I16: 1 | J16: 1 | L16: 0 | M16: 1 | O16: 1 | P16: 1 | AB16: 1 | AD16: 1 | AI16: 1 | AJ16: 1 | AK16: 0 | AL16: 1 | AR16: 1 | AS16: 1 | AV16: 1 | BC16: 0 | BD16: X | BE16: 1 | BW16: 1 | BX16: 0 | BY16: 0 | BZ16: 0 | CA16: 0 | CI16: 1 | CJ16: 1 | CK16: 1 | CL16: 1 | CQ16: 1 | CY16: 1
A17: =IF(Roster!$A$15<>"",Roster!$A$15,"") -> Jenna Nold | B17: 1 | C17: 1 | G17: 1 | H17: 1 | I17: 0 | J17: 1 | L17: 1 | M17: 1 | O17: 0 | P17: 0 | AB17: 1 | AD17: 1 | AI17: 1 | AJ17: 1 | AK17: 1 | AL17: 1 | AR17: 1 | AS17: 1 | AV17: 1 | BC17: 0 | BD17: 1 | BE17: 1 | BW17: 0 | BX17: 0 | BY17: 0 | BZ17: 0 | CA17: 0 | CI17: 1 | CJ17: 1 | CK17: 1 | CL17: 1 | CQ17: 1 | CY17: 1
A18: =IF(Roster!$A$16<>"",Roster!$A$16,"") -> Jimmy Towle | B18: 0 | C18: 0 | G18: 1 | H18: 0 | I18: 0 | J18: 1 | L18: 0 | M18: 0 | O18: 0 | P18: 0 | AB18: 0 | AD18: 1 | AI18: 0 | AJ18: 0 | AK18: 0 | AL18: 1 | AR18: 1 | AS18: 1 | AV18: 1 | BC18: 0 | BD18: 0 | BE18: 1 | BW18: 1 | BX18: 0 | BY18: 0 | BZ18: 0 | CA18: 0 | CI18: 1 | CJ18: 1 | CK18: 1 | CL18: 0 | CQ18: 1 | CY18: 1
A19: =IF(Roster!$A$17<>"",Roster!$A$17,"") -> Kailey Rugani | B19: 1 | C19: 1 | G19: 1 | H19: 1 | I19: 0 | J19: 1 | L19: 1 | M19: 1 | O19: 0 | P19: 0 | AB19: 1 | AD19: 1 | AI19: 1 | AJ19: 1 | AK19: 1 | AL19: 1 | AR19: 1 | AS19: 1 | AV19: 1 | BC19: 0 | BD19: 1 | BE19: 1 | BW19: 0 | BX19: 0 | BY19: 0 | BZ19: 1 | CA19: 0 | CI19: 1 | CJ19: 1 | CK19: 1 | CL19: 0 | CQ19: 1 | CY19: 1
A20: =IF(Roster!$A$18<>"",Roster!$A$18,"") -> Kasey Schock | B20: 1 | C20: 1 | G20: 1 | H20: 1 | I20: 0 | J20: 1 | L20: 1 | M20: 1 | O20: 0 | P20: 0 | AB20: 1 | AD20: 1 | AI20: 0 | AJ20: 1 | AK20: 1 | AL20: 1 | AR20: 1 | AS20: 1 | AV20: 1 | BC20: 0 | BD20: X | BE20: 1 | BW20: 0 | BX20: 0 | BY20: 0 | BZ20: 0 | CA20: 0 | CI20: 1 | CJ20: 1 | CK20: 1 | CL20: 0 | CQ20: 1 | CY20: 1
A21: =IF(Roster!$A$19<>"",Roster!$A$19,"") -> Kevin Nicholl | B21: 1 | C21: 1 | G21: 1 | H21: 1 | I21: 0 | J21: 1 | L21: 0 | M21: 1 | O21: 0 | P21: 0 | AB21: 1 | AD21: 1 | AI21: 1 | AJ21: 1 | AK21: 0 | AL21: 1 | AR21: 1 | AS21: 1 | AV21: 1 | BC21: X | BD21: X | BE21: 1 | BW21: 0 | BX21: 0 | BY21: 0 | BZ21: 0 | CA21: 0 | CI21: 1 | CJ21: 1 | CK21: 1 | CL21: 0 | CQ21: 1 | CY21: 1
A22: =IF(Roster!$A$20<>"",Roster!$A$20,"") -> Kit Asterin | B22: 1 | C22: 1 | G22: 1 | H22: 1 | I22: 0 | J22: 1 | L22: 1 | M22: 1 | O22: 0 | P22: 0 | AB22: 0 | AD22: 1 | AI22: 0 | AJ22: 1 | AK22: 1 | AL22: 1 | AR22: 1 | AS22: 1 | AV22: 0 | BC22: 0 | BD22: 1 | BE22: 1 | BW22: 1 | BX22: 0 | BY22: 0 | BZ22: 0 | CA22: 0 | CI22: 1 | CJ22: 0 | CK22: 1 | CL22: 1 | CQ22: 1 | CY22: 1
A23: =IF(Roster!$A$21<>"",Roster!$A$21,"") -> Kristin Dudley | B23: 1 | C23: 1 | G23: 1 | H23: 1 | I23: 1 | J23: 1 | L23: 0 | M23: 1 | O23: 1 | P23: 0 | AB23: 0 | AD23: 1 | AI23: 0 | AJ23: 1 | AK23: 0 | AL23: 1 | AR23: 1 | AS23: 1 | AV23: 0 | BC23: 0 | BD23: 1 | BE23: 0 | BW23: 1 | BX23: 0 | BY23: 0 | BZ23: 0 | CA23: 0 | CI23: 1 | CJ23: 0 | CK23: 1 | CL23: 0 | CQ23: 1 | CY23: 1
A24: =IF(Roster!$A$22<>"",Roster!$A$22,"") -> Lexie Thomas | B24: 1 | C24: 1 | G24: 1 | H24: 1 | I24: 0 | J24: 1 | L24: 0 | M24: 1 | O24: 0 | P24: 0 | AB24: 1 | AD24: 1 | AI24: 0 | AJ24: 1 | AK24: 0 | AL24: 1 | AR24: 1 | AS24: 1 | AV24: 0 | BC24: 1 | BD24: 1 | BE24: 1 | BW24: 1 | BX24: 0 | BY24: 0 | BZ24: 0 | CA24: 0 | CI24: 1 | CJ24: 0 | CK24: 1 | CL24: 0 | CQ24: 1 | CY24: 1
A25: =IF(Roster!$A$23<>"",Roster!$A$23,"") -> Lucas Jones | B25: 0 | C25: 0 | G25: 1 | H25: 0 | I25: 0 | J25: 1 | L25: 0 | M25: 0 | O25: 0 | P25: 0 | AB25: 0 | AD25: 0 | AI25: 0 | AJ25: 0 | AK25: 0 | AL25: 1 | AR25: X | AS25: 0 | AV25: 0 | BC25: 0 | BD25: 0 | BE25: 0 | BW25: 1 | BX25: 0 | BY25: 0 | BZ25: 0 | CA25: 0 | CI25: X | CJ25: X | CK25: X | CL25: 0 | CQ25: X | CY25: X
A26: =IF(Roster!$A$24<>"",Roster!$A$24,"") -> Max Sheppard | B26: 1 | C26: 0 | G26: X | H26: 1 | I26: 0 | J26: X | L26: 0 | M26: 1 | O26: 0 | P26: 0 | AB26: 1 | AD26: 0 | AI26: 0 | AJ26: 0 | AK26: 0 | AL26: X | AR26: 0 | AS26: 0 | AV26: 0 | BC26: X | BD26: 0 | BE26: 0 | BW26: 0 | BX26: 0 | BY26: 0 | BZ26: 0 | CA26: 0 | CI26: 0 | CJ26: 0 | CK26: 1 | CL26: 1 | CQ26: 1 | CY26: 1
A27: =IF(Roster!$A$25<>"",Roster!$A$25,"") -> Lucius Christie | B27: 1 | C27: 1 | G27: 1 | H27: 1 | I27: 0 | J27: 1 | L27: 0 | M27: 1 | O27: 0 | P27: 0 | AB27: 1 | AD27: 1 | AI27: 1 | AJ27: 1 | AK27: 0 | AL27: 1 | AR27: 1 | AS27: 1 | AV27: 1 | BC27: 1 | BD27: 1 | BE27: 1 | BW27: 1 | BX27: 0 | BY27: 0 | BZ27: 0 | CA27: 0 | CI27: 1 | CJ27: 1 | CK27: 1 | CL27: 1 | CQ27: 1 | CY27: 1
A28: =IF(Roster!$A$26<>"",Roster!$A$26,"") -> Patrick McMullen | B28: 1 | C28: 1 | G28: 1 | H28: 1 | I28: 0 | J28: 1 | L28: 1 | M28: 1 | O28: 0 | P28: 0 | AB28: 1 | AD28: 1 | AI28: 1 | AJ28: 1 | AK28: 1 | AL28: 1 | AR28: 1 | AS28: 1 | AV28: 1 | BC28: 0 | BD28: 1 | BE28: 1 | BW28: 1 | BX28: 0 | BY28: 0 | BZ28: 0 | CA28: 0 | CI28: 1 | CJ28: 1 | CK28: 1 | CL28: 0 | CQ28: 1 | CY28: 1
A29: =IF(Roster!$A$27<>"",Roster!$A$27,"") -> Rachel Graber | B29: 1 | C29: 1 | G29: 1 | H29: 1 | I29: 0 | J29: 1 | L29: 0 | M29: 1 | O29: 0 | P29: 0 | AB29: 0 | AD29: 1 | AI29: 0 | AJ29: 1 | AK29: 0 | AL29: 1 | AR29: 1 | AS29: 1 | AV29: 0 | BC29: 1 | BD29: 1 | BE29: 1 | BW29: 0 | BX29: 0 | BY29: 1 | BZ29: 0 | CA29: 0 | CI29: 1 | CJ29: 1 | CK29: 1 | CL29: 0 | CQ29: 1 | CY29: 1
A30: =IF(Roster!$A$28<>"",Roster!$A$28,"") -> Ryan Kindell | B30: 1 | C30: 1 | G30: 1 | H30: 1 | I30: 0 | J30: 1 | L30: 0 | M30: 1 | O30: 0 | P30: 0 | AB30: 1 | AD30: 1 | AI30: 1 | AJ30: 1 | AK30: 0 | AL30: 1 | AR30: 1 | AS30: 1 | AV30: 1 | BC30: X | BD30: 1 | BE30: 1 | BW30: 0 | BX30: 0 | BY30: 0 | BZ30: 0 | CA30: 0 | CI30: 1 | CJ30: 1 | CK30: 1 | CL30: 0 | CQ30: 1 | CY30: 1
A31: =IF(Roster!$A$29<>"",Roster!$A$29,"") -> Ryan Ward | B31: 1 | C31: 1 | G31: 1 | H31: 1 | I31: 0 | J31: 1 | L31: 0 | M31: 1 | O31: 0 | P31: 0 | AB31: 1 | AD31: 0 | AI31: 1 | AJ31: 1 | AK31: 0 | AL31: 1 | AR31: 1 | AS31: 0 | AV31: 0 | BC31: 1 | BD31: 1 | BE31: 0 | BW31: 0 | BX31: 0 | BY31: 0 | BZ31: 0 | CA31: 0 | CI31: 1 | CJ31: 1 | CK31: 1 | CL31: 0 | CQ31: 1 | CY31: 1
A32: =IF(Roster!$A$30<>"",Roster!$A$30,"") -> Sam Gombiner | B32: 0 | C32: 0 | G32: 1 | H32: 0 | I32: 0 | J32: 1 | L32: 0 | M32: 0 | O32: 0 | P32: 0 | AB32: 0 | AD32: 0 | AI32: 0 | AJ32: 0 | AK32: 0 | AL32: 1 | AR32: X | AS32: 0 | AV32: 0 | BC32: 0 | BD32: 0 | BE32: 0 | BW32: 0 | BX32: 0 | BY32: 0 | BZ32: 0 | CA32: 0 | CI32: X | CJ32: X | CK32: X | CL32: 0 | CQ32: X | CY32: X
A33: =IF(Roster!$A$31<>"",Roster!$A$31,"") -> Sarah Kingsley-Hart | B33: 1 | C33: 0 | G33: 1 | H33: 1 | I33: 0 | J33: 1 | L33: 0 | M33: 1 | O33: 0 | P33: 0 | AB33: 1 | AD33: 0 | AI33: 0 | AJ33: 0 | AK33: 0 | AL33: 1 | AR33: X | AS33: 0 | AV33: 0 | BC33: X | BD33: 0 | BE33: 0 | BW33: 0 | BX33: 0 | BY33: 0 | BZ33: 0 | CA33: 1 | CI33: X | CJ33: X | CK33: X | CL33: 0 | CQ33: X | CY33: X
A34: =IF(Roster!$A$32<>"",Roster!$A$32,"") -> Sarah Lynch | B34: 0 | C34: 0 | G34: 1 | H34: 0 | I34: 0 | J34: 1 | L34: 0 | M34: 0 | O34: 0 | P34: 0 | AB34: 0 | AD34: 1 | AI34: 0 | AJ34: 0 | AK34: 0 | AL34: 1 | AR34: X | AS34: 1 | AV34: 1 | BC34: 0 | BD34: 0 | BE34: X | BW34: 1 | BX34: 0 | BY34: 0 | BZ34: 0 | CA34: 0 | CI34: X | CJ34: X | CK34: X | CL34: 0 | CQ34: X | CY34: X
A35: =IF(Roster!$A$33<>"",Roster!$A$33,"") -> Shani Rosenthal | B35: 1 | C35: 1 | G35: 1 | H35: 1 | I35: 1 | J35: 1 | L35: 0 | M35: 1 | O35: 1 | P35: 0 | AB35: 0 | AD35: 1 | AI35: 0 | AJ35: 1 | AK35: 0 | AL35: 1 | AR35: 1 | AS35: 1 | AV35: 0 | BC35: 0 | BD35: 1 | BE35: 1 | BW35: 0 | BX35: 0 | BY35: 0 | BZ35: 1 | CA35: 0 | CI35: 1 | CJ35: 0 | CK35: 1 | CL35: 0 | CQ35: 1 | CY35: 1
A36: =IF(Roster!$A$34<>"",Roster!$A$34,"") -> Vivian Shen | B36: 1 | C36: X | G36: 1 | H36: 1 | I36: 1 | J36: 1 | L36: 0 | M36: 1 | O36: 1 | P36: 1 | AB36: 1 | AD36: 0 | AI36: 1 | AJ36: 1 | AK36: 0 | AL36: 1 | AR36: 1 | AS36: 0 | AV36: 0 | BC36: 0 | BD36: 1 | BE36: 0 | BW36: 1 | BX36: 0 | BY36: 0 | BZ36: 0 | CA36: 0 | CI36: 1 | CJ36: 1 | CK36: 1 | CL36: 0 | CQ36: 1 | CY36: 1
A37: =IF(Roster!$A$35<>"",Roster!$A$35,"") -> Zach Esakof | B37: X | C37: 0 | G37: 1 | H37: 0 | I37: 0 | J37: 1 | L37: 0 | M37: 1 | O37: 0 | P37: 0 | AB37: 1 | AD37: X | AI37: 0 | AJ37: 0 | AK37: 0 | AL37: 1 | AR37: X | AS37: 1 | AV37: 1 | BC37: X | BD37: 0 | BE37: 1 | BW37: 1 | BX37: 0 | BY37: 0 | BZ37: 0 | CA37: 0 | CI37: X | CJ37: X | CK37: X | CL37: X | CQ37: X | CY37: X
A38: =IF(Roster!$A$36<>"",Roster!$A$36,"") -> Annette Kukunas-Piper | B38: X | C38: X | G38: X | H38: X | I38: 0 | J38: 1 | L38: X | M38: X | O38: 0 | P38: 0 | AB38: X | AD38: X | AI38: X | AJ38: X | AK38: 1 | AL38: X | AR38: X | AS38: X | AV38: X | BC38: X | BD38: 1 | BE38: 1 | BW38: 0 | BX38: 1 | BY38: 0 | BZ38: 0 | CA38: 0 | CI38: X | CJ38: X | CK38: X | CQ38: X | CY38: X
A39: =IF(Roster!$A$37<>"",Roster!$A$37,"") -> Matt Duffy | B39: X | C39: X | G39: X | H39: X | I39: 0 | J39: 1 | L39: X | M39: X | O39: 0 | P39: 0 | AB39: X | AD39: X | AI39: X | AJ39: X | AK39: 1 | AL39: X | AR39: X | AS39: X | AV39: X | BC39: X | BD39: 1 | BE39: 1 | BW39: 1 | BX39: 0 | BY39: 0 | BZ39: 0 | CA39: 0 | CI39: X | CJ39: X | CK39: X | CQ39: X | CY39: X
